Workbook

Sheet Dashboard
B1: RENT-A-VACATION
B2: QA Scenario Test Dashboard
B3: Generated: April 06, 2026
B5: LATEST RUN SUMMARY
B7: Total Scenarios | D7: Passed | F7: Failed | H7: Blocked
B8: =COUNTIF(Summary!A3:A200,"S-*") -> 30 | D8: =Summary!B33 -> 0 | F8: =Summary!C33 -> 0 | H8: =Summary!D33 -> 0
B11: Skipped | D11: Pass Rate | F11: Execution Coverage | H11: Total Steps
B12: =Summary!E33 -> 0 | D12: =IF(Summary!B33+Summary!C33>0,Summary!B33/(Summary!B33+Summary!C33),0) -> 0 | F12: =IF(COUNTIF(Summary!A3:A200,"S-*")>0,COUNTIF(Summary!R3:R200,"<>")/COUNTIF(Summary!A3:A200,"S-*"),0) -> 1 | H12: =SUM(Summary!F3:F32) -> 267
B15: STATUS DISTRIBUTION & TREND
B32: RESULTS BY TIER
B34: Tier | C34: Scenarios | D34: Passed | E34: Failed | F34: Blocked | G34: Pass Rate | H34: Progress
B35: Foundation | C35: 4 | D35: =IF(Summary!R3="PASS",1,0)+IF(Summary!R5="PASS",1,0)+IF(Summary!R22="PASS",1,0)+IF(Summary!R24="PASS",1,0) -> 0 | E35: =IF(Summary!R3="FAIL",1,0)+IF(Summary!R5="FAIL",1,0)+IF(Summary!R22="FAIL",1,0)+IF(Summary!R24="FAIL",1,0) -> 0 | F35: =IF(Summary!R3="BLOCKED",1,0)+IF(Summary!R5="BLOCKED",1,0)+IF(Summary!R22="BLOCKED",1,0)+IF(Summary!R24="BLOCKED",1,0) -> 0 | G35: =IF(D35+E35>0,D35/(D35+E35),0) -> 0 | H35: =G35 -> 0
B36: Core Marketplace | C36: 5 | D36: =IF(Summary!R6="PASS",1,0)+IF(Summary!R7="PASS",1,0)+IF(Summary!R8="PASS",1,0)+IF(Summary!R21="PASS",1,0)+IF(Summary!R25="PASS",1,0) -> 0 | E36: =IF(Summary!R6="FAIL",1,0)+IF(Summary!R7="FAIL",1,0)+IF(Summary!R8="FAIL",1,0)+IF(Summary!R21="FAIL",1,0)+IF(Summary!R25="FAIL",1,0) -> 0 | F36: =IF(Summary!R6="BLOCKED",1,0)+IF(Summary!R7="BLOCKED",1,0)+IF(Summary!R8="BLOCKED",1,0)+IF(Summary!R21="BLOCKED",1,0)+IF(Summary!R25="BLOCKED",1,0) -> 0 | G36: =IF(D36+E36>0,D36/(D36+E36),0) -> 0 | H36: =G36 -> 0
B37: Communication | C37: 6 | D37: =IF(Summary!R9="PASS",1,0)+IF(Summary!R10="PASS",1,0)+IF(Summary!R11="PASS",1,0)+IF(Summary!R12="PASS",1,0)+IF(Summary!R13="PASS",1,0)+IF(Summary!R19="PASS",1,0) -> 0 | E37: =IF(Summary!R9="FAIL",1,0)+IF(Summary!R10="FAIL",1,0)+IF(Summary!R11="FAIL",1,0)+IF(Summary!R12="FAIL",1,0)+IF(Summary!R13="FAIL",1,0)+IF(Summary!R19="FAIL",1,0) -> 0 | F37: =IF(Summary!R9="BLOCKED",1,0)+IF(Summary!R10="BLOCKED",1,0)+IF(Summary!R11="BLOCKED",1,0)+IF(Summary!R12="BLOCKED",1,0)+IF(Summary!R13="BLOCKED",1,0)+IF(Summary!R19="BLOCKED",1,0) -> 0 | G37: =IF(D37+E37>0,D37/(D37+E37),0) -> 0 | H37: =G37 -> 0
B38: Business Ops | C38: 5 | D38: =IF(Summary!R14="PASS",1,0)+IF(Summary!R15="PASS",1,0)+IF(Summary!R16="PASS",1,0)+IF(Summary!R17="PASS",1,0)+IF(Summary!R18="PASS",1,0) -> 0 | E38: =IF(Summary!R14="FAIL",1,0)+IF(Summary!R15="FAIL",1,0)+IF(Summary!R16="FAIL",1,0)+IF(Summary!R17="FAIL",1,0)+IF(Summary!R18="FAIL",1,0) -> 0 | F38: =IF(Summary!R14="BLOCKED",1,0)+IF(Summary!R15="BLOCKED",1,0)+IF(Summary!R16="BLOCKED",1,0)+IF(Summary!R17="BLOCKED",1,0)+IF(Summary!R18="BLOCKED",1,0) -> 0 | G38: =IF(D38+E38>0,D38/(D38+E38),0) -> 0 | H38: =G38 -> 0
B39: Admin & Platform | C39: 7 | D39: =IF(Summary!R4="PASS",1,0)+IF(Summary!R20="PASS",1,0)+IF(Summary!R26="PASS",1,0)+IF(Summary!R27="PASS",1,0)+IF(Summary!R28="PASS",1,0)+IF(Summary!R29="PASS",1,0)+IF(Summary!R30="PASS",1,0) -> 0 | E39: =IF(Summary!R4="FAIL",1,0)+IF(Summary!R20="FAIL",1,0)+IF(Summary!R26="FAIL",1,0)+IF(Summary!R27="FAIL",1,0)+IF(Summary!R28="FAIL",1,0)+IF(Summary!R29="FAIL",1,0)+IF(Summary!R30="FAIL",1,0) -> 0 | F39: =IF(Summary!R4="BLOCKED",1,0)+IF(Summary!R20="BLOCKED",1,0)+IF(Summary!R26="BLOCKED",1,0)+IF(Summary!R27="BLOCKED",1,0)+IF(Summary!R28="BLOCKED",1,0)+IF(Summary!R29="BLOCKED",1,0)+IF(Summary!R30="BLOCKED",1,0) -> 0 | G39: =IF(D39+E39>0,D39/(D39+E39),0) -> 0 | H39: =G39 -> 0
B40: Edge Cases | C40: 2 | D40: =IF(Summary!R23="PASS",1,0)+IF(Summary!R31="PASS",1,0) -> 0 | E40: =IF(Summary!R23="FAIL",1,0)+IF(Summary!R31="FAIL",1,0) -> 0 | F40: =IF(Summary!R23="BLOCKED",1,0)+IF(Summary!R31="BLOCKED",1,0) -> 0 | G40: =IF(D40+E40>0,D40/(D40+E40),0) -> 0 | H40: =G40 -> 0
B41: Master Validation | C41: 1 | D41: =IF(Summary!R32="PASS",1,0) -> 0 | E41: =IF(Summary!R32="FAIL",1,0) -> 0 | F41: =IF(Summary!R32="BLOCKED",1,0) -> 0 | G41: =IF(D41+E41>0,D41/(D41+E41),0) -> 0 | H41: =G41 -> 0
B50: Status | C50: Count
B51: Passed | C51: =Summary!B33 -> 0
B52: Failed | C52: =Summary!C33 -> 0
B53: Blocked | C53: =Summary!D33 -> 0
B54: Skipped | C54: =Summary!E33 -> 0
B55: Not Run | C55: =COUNTIF(Summary!A3:A200,"S-*")-Summary!B33-Summary!C33-Summary!D33-Summary!E33 -> 30
B58: Tier | C58: Passed | D58: Failed | E58: Blocked
B59: Foundation | C59: =D35 -> 0 | D59: =E35 -> 0 | E59: =F35 -> 0
B60: SCENARIO HEALTH MAP
B61: =IF(Summary!R3<>"","S-01" & CHAR(10) & Summary!R3,"S-01") -> S-01 | C61: =IF(Summary!R4<>"","S-02" & CHAR(10) & Summary!R4,"S-02") -> S-02 | D61: =IF(Summary!R5<>"","S-03" & CHAR(10) & Summary!R5,"S-03") -> S-03 | E61: =IF(Summary!R6<>"","S-04" & CHAR(10) & Summary!R6,"S-04") -> S-04 | F61: =IF(Summary!R7<>"","S-05" & CHAR(10) & Summary!R7,"S-05") -> S-05 | G61: =IF(Summary!R8<>"","S-06" & CHAR(10) & Summary!R8,"S-06") -> S-06
B62: =IF(Summary!R9<>"","S-07" & CHAR(10) & Summary!R9,"S-07") -> S-07 | C62: =IF(Summary!R10<>"","S-08" & CHAR(10) & Summary!R10,"S-08") -> S-08 | D62: =IF(Summary!R11<>"","S-09" & CHAR(10) & Summary!R11,"S-09") -> S-09 | E62: =IF(Summary!R12<>"","S-10" & CHAR(10) & Summary!R12,"S-10") -> S-10 | F62: =IF(Summary!R13<>"","S-11" & CHAR(10) & Summary!R13,"S-11") -> S-11 | G62: =IF(Summary!R14<>"","S-12" & CHAR(10) & Summary!R14,"S-12") -> S-12
B63: =IF(Summary!R15<>"","S-13" & CHAR(10) & Summary!R15,"S-13") -> S-13 | C63: =IF(Summary!R16<>"","S-14" & CHAR(10) & Summary!R16,"S-14") -> S-14 | D63: =IF(Summary!R17<>"","S-15" & CHAR(10) & Summary!R17,"S-15") -> S-15 | E63: =IF(Summary!R18<>"","S-16" & CHAR(10) & Summary!R18,"S-16") -> S-16 | F63: =IF(Summary!R19<>"","S-17" & CHAR(10) & Summary!R19,"S-17") -> S-17 | G63: =IF(Summary!R20<>"","S-18" & CHAR(10) & Summary!R20,"S-18") -> S-18
B64: =IF(Summary!R21<>"","S-19" & CHAR(10) & Summary!R21,"S-19") -> S-19 | C64: =IF(Summary!R22<>"","S-20" & CHAR(10) & Summary!R22,"S-20") -> S-20 | D64: =IF(Summary!R23<>"","S-21" & CHAR(10) & Summary!R23,"S-21") -> S-21 | E64: =IF(Summary!R24<>"","S-22" & CHAR(10) & Summary!R24,"S-22") -> S-22 | F64: =IF(Summary!R25<>"","S-23" & CHAR(10) & Summary!R25,"S-23") -> S-23 | G64: =IF(Summary!R26<>"","S-24" & CHAR(10) & Summary!R26,"S-24") -> S-24
B65: =IF(Summary!R27<>"","S-25" & CHAR(10) & Summary!R27,"S-25") -> S-25 | C65: =IF(Summary!R28<>"","S-26" & CHAR(10) & Summary!R28,"S-26") -> S-26 | D65: =IF(Summary!R29<>"","S-27" & CHAR(10) & Summary!R29,"S-27") -> S-27 | E65: =IF(Summary!R30<>"","S-28" & CHAR(10) & Summary!R30,"S-28") -> S-28 | F65: =IF(Summary!R31<>"","S-29" & CHAR(10) & Summary!R31,"S-29") -> S-29 | G65: =IF(Summary!R32<>"","S-30" & CHAR(10) & Summary!R32,"S-30") -> S-30
B67: DEFECT TRACKER
B68: # | C68: Scenario | D68: Step | E68: Severity | F68: GitHub Issue | G68: Status | H68: Found Date | I68: Resolved Date | J68: Notes
B69: 1 | C69: =COUNTIF(Summary!H3:H32,"PASS") -> 0 | D69: =COUNTIF(Summary!H3:H32,"FAIL") -> 0 | E69: =COUNTIF(Summary!H3:H32,"BLOCKED") -> 0
B70: 2 | C70: =COUNTIF(Summary!I3:I32,"PASS") -> 0 | D70: =COUNTIF(Summary!I3:I32,"FAIL") -> 0 | E70: =COUNTIF(Summary!I3:I32,"BLOCKED") -> 0
B71: 3 | C71: =COUNTIF(Summary!J3:J32,"PASS") -> 0 | D71: =COUNTIF(Summary!J3:J32,"FAIL") -> 0 | E71: =COUNTIF(Summary!J3:J32,"BLOCKED") -> 0
B72: 4 | C72: =COUNTIF(Summary!K3:K32,"PASS") -> 0 | D72: =COUNTIF(Summary!K3:K32,"FAIL") -> 0 | E72: =COUNTIF(Summary!K3:K32,"BLOCKED") -> 0
B73: 5 | C73: =COUNTIF(Summary!L3:L32,"PASS") -> 0 | D73: =COUNTIF(Summary!L3:L32,"FAIL") -> 0 | E73: =COUNTIF(Summary!L3:L32,"BLOCKED") -> 0
B74: 6 | C74: =COUNTIF(Summary!M3:M32,"PASS") -> 0 | D74: =COUNTIF(Summary!M3:M32,"FAIL") -> 0 | E74: =COUNTIF(Summary!M3:M32,"BLOCKED") -> 0
...

Sheet Run Log
A1: Test Run Log
A3: Run # | B3: Date | C3: Tester | D3: Environment | E3: Seed Version | F3: Scenarios Attempted | G3: Passed | H3: Failed | I3: Blocked | J3: Skipped | K3: Pass Rate | L3: Duration | M3: Notes / Issues Found
A4: 1 | K4: =IF(G4+H4>0,G4/(G4+H4),"")
A5: 2 | K5: =IF(G5+H5>0,G5/(G5+H5),"")
A6: 3 | K6: =IF(G6+H6>0,G6/(G6+H6),"")
A7: 4 | K7: =IF(G7+H7>0,G7/(G7+H7),"")
A8: 5 | K8: =IF(G8+H8>0,G8/(G8+H8),"")
A9: 6 | K9: =IF(G9+H9>0,G9/(G9+H9),"")
A10: 7 | K10: =IF(G10+H10>0,G10/(G10+H10),"")
A11: 8 | K11: =IF(G11+H11>0,G11/(G11+H11),"")
A12: 9 | K12: =IF(G12+H12>0,G12/(G12+H12),"")
A13: 10 | K13: =IF(G13+H13>0,G13/(G13+H13),"")
A14: 11 | K14: =IF(G14+H14>0,G14/(G14+H14),"")
A15: 12 | K15: =IF(G15+H15>0,G15/(G15+H15),"")
... A23: 20 | K23: =IF(G23+H23>0,G23/(G23+H23),"")

Sheet Summary
A1: Scenario Test Summary
A2: ID | B2: Scenario Name | C2: Tier | D2: Roles | E2: Est. Time | F2: Steps | G2: Preconditions | H2: Run 1 | I2: Run 2 | J2: Run 3 | K2: Run 4 | L2: Run 5 | M2: Run 6 | N2: Run 7 | O2: Run 8 | P2: Run 9 | Q2: Run 10 | R2: Latest Status | S2: Bug Issues
A3: S-01 | B3: New User Onboarding & Approval | C3: Foundation | D3: New User, RAV Admin | E3: 10 min | F3: 8 | G3: Use an email not in the system (e.g., testuser-[date]@gmail.com) | R3: =IF(Q3<>"",Q3,IF(P3<>"",P3,IF(O3<>"",O3,IF(N3<>"",N3,IF(M3<>"",M3,IF(L3<>"",L3,IF(K3<>"",K3,IF(J3<>"",J3,IF(I3<>"",I3,IF(H3<>"",H3,""))))))))))
A4: S-02 | B4: Owner Role Upgrade & Verification | C4: Admin & Platform | D4: Renter 4, RAV Admin | E4: 10 min | F4: 10 | G4: Renter 4 (renter004@) has approved renter account, no owner role | R4: =IF(Q4<>"",Q4,IF(P4<>"",P4,IF(O4<>"",O4,IF(N4<>"",N4,IF(M4<>"",M4,IF(L4<>"",L4,IF(K4<>"",K4,IF(J4<>"",J4,IF(I4<>"",I4,IF(H4<>"",H4,""))))))))))
A5: S-03 | B5: Property Listing Creation & Approval | C5: Foundation | D5: Owner 1 (Alex, Pro), RAV Admin | E5: 12 min | F5: 12 | G5: Owner 1 logged in, not at listing limit (Pro = 10) | R5: =IF(Q5<>"",Q5,IF(P5<>"",P5,IF(O5<>"",O5,IF(N5<>"",N5,IF(M5<>"",M5,IF(L5<>"",L5,IF(K5<>"",K5,IF(J5<>"",J5,IF(I5<>"",I5,IF(H5<>"",H5,""))))))))))
A6: S-04 | B6: Direct Booking — Happy Path | C6: Core Marketplace | D6: Renter 1, Owner 1, RAV Admin | E6: 15 min | F6: 12 | G6: Active listing from Owner 1 with direct booking (non-bidding) | R6: =IF(Q6<>"",Q6,IF(P6<>"",P6,IF(O6<>"",O6,IF(N6<>"",N6,IF(M6<>"",M6,IF(L6<>"",L6,IF(K6<>"",K6,IF(J6<>"",J6,IF(I6<>"",I6,IF(H6<>"",H6,""))))))))))
A7: S-05 | B7: Bidding & Counter-Offer Workflow | C7: Core Marketplace | D7: Renter 1, Owner 1 | E7: 15 min | F7: 11 | G7: Active listing from Owner 1 with open_for_bidding = true | R7: =IF(Q7<>"",Q7,IF(P7<>"",P7,IF(O7<>"",O7,IF(N7<>"",N7,IF(M7<>"",M7,IF(L7<>"",L7,IF(K7<>"",K7,IF(J7<>"",J7,IF(I7<>"",I7,IF(H7<>"",H7,""))))))))))
A8: S-06 | B8: Travel Request & Owner Proposal | C8: Core Marketplace | D8: Renter 2 (Liam), Owner 2 (Maria, Marriott) | E8: 15 min | F8: 10 | G8: Owner 2 has active Marriott listings in Orlando | R8: =IF(Q8<>"",Q8,IF(P8<>"",P8,IF(O8<>"",O8,IF(N8<>"",N8,IF(M8<>"",M8,IF(L8<>"",L8,IF(K8<>"",K8,IF(J8<>"",J8,IF(I8<>"",I8,IF(H8<>"",H8,""))))))))))
A9: S-07 | B9: Pre-Booking Inquiry & Messaging | C9: Communication | D9: Renter 3 (Olivia, Premium), Owner 3 (James, Disney) | E9: 8 min | F9: 7 | G9: Owner 3 has active Disney listing | R9: =IF(Q9<>"",Q9,IF(P9<>"",P9,IF(O9<>"",O9,IF(N9<>"",N9,IF(M9<>"",M9,IF(L9<>"",L9,IF(K9<>"",K9,IF(J9<>"",J9,IF(I9<>"",I9,IF(H9<>"",H9,""))))))))))
A10: S-08 | B10: Booking Messaging & Realtime | C10: Communication | D10: Renter 1, Owner 1 | E10: 8 min | F10: 6 | G10: Confirmed booking between Renter 1 and Owner 1 | R10: =IF(Q10<>"",Q10,IF(P10<>"",P10,IF(O10<>"",O10,IF(N10<>"",N10,IF(M10<>"",M10,IF(L10<>"",L10,IF(K10<>"",K10,IF(J10<>"",J10,IF(I10<>"",I10,IF(H10<>"",H10,""))))))))))
A11: S-09 | B11: Renter Cancellation Flow | C11: Communication | D11: Renter 1, Owner 1, RAV Admin | E11: 10 min | F11: 8 | G11: Confirmed booking between Renter 1 and Owner 1 | R11: =IF(Q11<>"",Q11,IF(P11<>"",P11,IF(O11<>"",O11,IF(N11<>"",N11,IF(M11<>"",M11,IF(L11<>"",L11,IF(K11<>"",K11,IF(J11<>"",J11,IF(I11<>"",I11,IF(H11<>"",H11,""))))))))))
A12: S-10 | B12: Owner Cancellation Flow | C12: Communication | D12: Owner 1, Renter 1, RAV Admin | E12: 10 min | F12: 7 | G12: Confirmed booking between Owner 1 and Renter 1 | R12: =IF(Q12<>"",Q12,IF(P12<>"",P12,IF(O12<>"",O12,IF(N12<>"",N12,IF(M12<>"",M12,IF(L12<>"",L12,IF(K12<>"",K12,IF(J12<>"",J12,IF(I12<>"",I12,IF(H12<>"",H12,""))))))))))
A13: S-11 | B13: Dispute Resolution — Check-In Issue | C13: Communication | D13: Renter 1, RAV Admin | E13: 12 min | F13: 8 | G13: Confirmed booking at/past check-in date | R13: =IF(Q13<>"",Q13,IF(P13<>"",P13,IF(O13<>"",O13,IF(N13<>"",N13,IF(M13<>"",M13,IF(L13<>"",L13,IF(K13<>"",K13,IF(J13<>"",J13,IF(I13<>"",I13,IF(H13<>"",H13,""))))))))))
A14: S-12 | B14: Owner Earnings & Payout Cycle | C14: Business Ops | D14: Owner 2 (Maria, Business), RAV Admin | E14: 10 min | F14: 7 | G14: Completed booking for Owner 2 with escrow released | R14: =IF(Q14<>"",Q14,IF(P14<>"",P14,IF(O14<>"",O14,IF(N14<>"",N14,IF(M14<>"",M14,IF(L14<>"",L14,IF(K14<>"",K14,IF(J14<>"",J14,IF(I14<>"",I14,IF(H14<>"",H14,""))))))))))
... A32: S-30 | B32: Complete Marketplace Cycle | C32: Master Validation | D32: Owner 1, Renter 1, RAV Admin | E32: 25 min | F32: 18 | G32: Reseeded DEV data recommended | R32: =IF(Q32<>"",Q32,IF(P32<>"",P32,IF(O32<>"",O32,IF(N32<>"",N32,IF(M32<>"",M32,IF(L32<>"",L32,IF(K32<>"",K32,IF(J32<>"",J32,IF(I32<>"",I32,IF(H32<>"",H32,""))))))))))
A33: TOTALS | B33: =COUNTIF(R3:R32,"PASS") -> 0 | C33: =COUNTIF(R3:R32,"FAIL") -> 0 | D33: =COUNTIF(R3:R32,"BLOCKED") -> 0 | E33: =COUNTIF(R3:R32,"SKIP") -> 0
B34: Passed | C34: Failed | D34: Blocked | E34: Skipped

Sheet S-01 New User Onboarding & Appr
A1: S-01: New User Onboarding & Approval
A3: Capability: | B3: Signup → Approval → Access
A4: Roles: | B4: New User, RAV Admin
A5: Est. Time: | B5: 10 min
A6: Preconditions: | B6: Use an email not in the system (e.g., testuser-[date]@gmail.com)
A8: # | B8: As (Role) | C8: Action | D8: Page | E8: Expected Result | F8: Run 1 | G8: Run 2 | H8: Run 3 | I8: Run 4 | J8: Run 5 | K8: Run 6 | L8: Run 7 | M8: Run 8 | N8: Run 9 | O8: Run 10 | P8: Notes / Bug #
A9: 1 | B9: New User | C9: Open incognito → /signup | D9: /signup | E9: Signup form loads with email + password + Google OAuth
A10: 2 | B10: New User | C10: Enter name, email, password → Submit | D10: /signup | E10: Success message, redirected to /pending-approval
A11: 3 | B11: New User | C11: Try navigating to /rentals | D11: /rentals | E11: Blocked — redirected to /pending-approval
A12: 4 | B12: Admin | C12: Log in as dev-admin@rent-a-vacation.com | D12: /login | E12: Dashboard loads
A13: 5 | B13: Admin | C13: Navigate to /admin?tab=pending-approvals | D13: /admin | E13: New user in pending list
A14: 6 | B14: Admin | C14: Click Approve on the new user | D14: /admin | E14: Status changes to approved
A15: 7 | B15: New User | C15: Refresh or re-login | D15: — | E15: Redirected to /rentals — full access
A16: 8 | B16: New User | C16: Browse /rentals, click a listing | D16: /property/:id | E16: Property details load
A18: SCENARIO RESULT

Sheet S-02 Owner Role Upgrade & Verif
A1: S-02: Owner Role Upgrade & Verification
A3: Capability: | B3: Role upgrade → Doc upload → Admin verify
A4: Roles: | B4: Renter 4, RAV Admin
A5: Est. Time: | B5: 10 min
A6: Preconditions: | B6: Renter 4 (renter004@) has approved renter account, no owner role
A8: # | B8: As (Role) | C8: Action | D8: Page | E8: Expected Result | F8: Run 1 | G8: Run 2 | H8: Run 3 | I8: Run 4 | J8: Run 5 | K8: Run 6 | L8: Run 7 | M8: Run 8 | N8: Run 9 | O8: Run 10 | P8: Notes / Bug #
A9: 1 | B9: Renter 4 | C9: Log in → /owner-dashboard | D9: /owner-dashboard | E9: RoleUpgradeDialog appears
A10: 2 | B10: Renter 4 | C10: Submit role upgrade request | D10: /owner-dashboard | E10: Toast: Request submitted
A11: 3 | B11: Admin | C11: Log in → /admin?tab=pending-approvals | D11: /admin | E11: Role upgrade request visible
A12: 4 | B12: Admin | C12: Approve role upgrade | D12: /admin | E12: Renter 4 now has property_owner role
A13: 5 | B13: Renter 4 | C13: Refresh page or re-login | D13: /owner-dashboard | E13: Owner dashboard loads (no upgrade dialog)
A14: 6 | B14: Renter 4 | C14: Account tab → Verification section | D14: /owner-dashboard?tab=account | E14: Upload fields visible
A15: 7 | B15: Renter 4 | C15: Upload verification documents | D15: /owner-dashboard?tab=account | E15: Status: Pending verification
A16: 8 | B16: Admin | C16: /admin?tab=verifications | D16: /admin | E16: Docs in verification queue
A17: 9 | B17: Admin | C17: Review and approve verification | D17: /admin | E17: Status: Verified
A18: 10 | B18: Renter 4 | C18: Refresh Account tab | D18: /owner-dashboard?tab=account | E18: Verification badge: Verified
A20: SCENARIO RESULT

Sheet S-03 Property Listing Creation 
A1: S-03: Property Listing Creation & Approval
A3: Capability: | B3: List property → Admin review → Goes live
A4: Roles: | B4: Owner 1 (Alex, Pro), RAV Admin
A5: Est. Time: | B5: 12 min
A6: Preconditions: | B6: Owner 1 logged in, not at listing limit (Pro = 10)
A8: # | B8: As (Role) | C8: Action | D8: Page | E8: Expected Result | F8: Run 1 | G8: Run 2 | H8: Run 3 | I8: Run 4 | J8: Run 5 | K8: Run 6 | L8: Run 7 | M8: Run 8 | N8: Run 9 | O8: Run 10 | P8: Notes / Bug #
A9: 1 | B9: Owner 1 | C9: Navigate to /list-property | D9: /list-property | E9: 3-step form loads
A10: 2 | B10: Owner 1 | C10: Step 1: Fill property details (Las Vegas, Hilton, 2BR/2BA, sleeps 6) | D10: /list-property | E10: Fields accept input, amenities work
A11: 3 | B11: Owner 1 | C11: Click Next | D11: /list-property | E11: Step 2: Dates & Pricing
A12: 4 | B12: Owner 1 | C12: Step 2: Check-in 60d out, 7 nights, $200/night, Moderate cancel, Open for Bidding | D12: /list-property | E12: Price: $1,400 owner + $210 markup = $1,610
A13: 5 | B13: Owner 1 | C13: Click Next | D13: /list-property | E13: Step 3: Review & Submit
A14: 6 | B14: Owner 1 | C14: Review → Submit for Review | D14: /list-property | E14: Redirected to /owner-dashboard?tab=my-listings
A15: 7 | B15: Owner 1 | C15: Check My Listings tab | D15: /owner-dashboard | E15: Status: Pending Approval
A16: 8 | B16: Admin | C16: Log in → /admin?tab=listings | D16: /admin | E16: New listing in pending queue
A17: 9 | B17: Admin | C17: Review → Approve | D17: /admin | E17: Status: Active
A18: 10 | B18: Owner 1 | C18: Refresh My Listings | D18: /owner-dashboard | E18: Status: Active
A19: 11 | B19: Renter 1 | C19: Log in → /rentals → search Las Vegas | D19: /rentals | E19: New listing appears
A20: 12 | B20: Renter 1 | C20: Click listing | D20: /property/:id | E20: Full details visible with bidding badge
A22: SCENARIO RESULT

Sheet S-04 Direct Booking — Happy Pat
A1: S-04: Direct Booking — Happy Path
A3: Capability: | B3: Browse → Book → Pay → Owner confirm → Escrow
A4: Roles: | B4: Renter 1, Owner 1, RAV Admin
A5: Est. Time: | B5: 15 min
A6: Preconditions: | B6: Active listing from Owner 1 with direct booking (non-bidding)
A8: # | B8: As (Role) | C8: Action | D8: Page | E8: Expected Result | F8: Run 1 | G8: Run 2 | H8: Run 3 | I8: Run 4 | J8: Run 5 | K8: Run 6 | L8: Run 7 | M8: Run 8 | N8: Run 9 | O8: Run 10 | P8: Notes / Bug #
A9: 1 | B9: Renter 1 | C9: Log in → /rentals → find Owner 1 fixed-price listing | D9: /rentals | E9: Listing visible with price
A10: 2 | B10: Renter 1 | C10: Click listing → view details | D10: /property/:id | E10: Price breakdown, cancellation policy detail
A11: 3 | B11: Renter 1 | C11: Click Book Now | D11: /checkout | E11: Checkout with fee breakdown, Stripe form
A12: 4 | B12: Renter 1 | C12: Pay with test card 4242...4242 | D12: /checkout | E12: Redirect to /booking-success
A13: 5 | B13: Renter 1 | C13: View booking confirmation | D13: /booking-success | E13: Timeline: Payment ✅, Owner Confirm ⏳
A14: 6 | B14: Owner 1 | C14: Log in → check notification bell | D14: Any page | E14: Notification: New booking
A15: 7 | B15: Owner 1 | C15: /owner-dashboard?tab=bookings-earnings | D15: /owner-dashboard | E15: Booking with Confirm button + countdown
A16: 8 | B16: Owner 1 | C16: Confirm → enter resort confirmation RST123456 | D16: /owner-dashboard | E16: Status: Confirmed
A17: 9 | B17: Renter 1 | C17: /my-trips?tab=bookings | D17: /my-trips | E17: Booking: Confirmed, timeline updated
A18: 10 | B18: Admin | C18: /admin?tab=escrow | D18: /admin | E18: Escrow: Pending Verification
A19: 11 | B19: Admin | C19: Verify confirmation → Release escrow | D19: /admin | E19: Escrow: Released
A20: 12 | B20: Owner 1 | C20: Check Bookings & Earnings | D20: /owner-dashboard | E20: Earnings updated, payout visible
A22: SCENARIO RESULT

Sheet S-05 Bidding & Counter-Offer Wo
A1: S-05: Bidding & Counter-Offer Workflow
A3: Capability: | B3: Bid → Counter → Accept → Booking
A4: Roles: | B4: Renter 1, Owner 1
A5: Est. Time: | B5: 15 min
A6: Preconditions: | B6: Active listing from Owner 1 with open_for_bidding = true
A8: # | B8: As (Role) | C8: Action | D8: Page | E8: Expected Result | F8: Run 1 | G8: Run 2 | H8: Run 3 | I8: Run 4 | J8: Run 5 | K8: Run 6 | L8: Run 7 | M8: Run 8 | N8: Run 9 | O8: Run 10 | P8: Notes / Bug #
A9: 1 | B9: Renter 1 | C9: /rentals → find bidding listing from Owner 1 | D9: /rentals | E9: Open for Bidding badge visible
A10: 2 | B10: Renter 1 | C10: Click listing → Place Bid | D10: /property/:id | E10: BidFormDialog opens
A11: 3 | B11: Renter 1 | C11: Bid at 80% of list price, 4 guests, add message → Submit | D11: /property/:id | E11: Toast: Bid submitted
A12: 4 | B12: Renter 1 | C12: /my-trips?tab=offers | D12: /my-trips | E12: Bid: Pending
A13: 5 | B13: Owner 1 | C13: Log in → check notification bell | D13: Any | E13: Notification: New bid received
A14: 6 | B14: Owner 1 | C14: My Listings → View Bids (BidsManagerDialog) | D14: /owner-dashboard | E14: Renter 1's bid visible
A15: 7 | B15: Owner 1 | C15: Counter at 90% of list price with message → Submit | D15: /owner-dashboard | E15: Counter-offer sent
A16: 8 | B16: Renter 1 | C16: Check /my-trips?tab=offers | D16: /my-trips | E16: Counter-offer amount + message shown
A17: 9 | B17: Renter 1 | C17: Accept counter-offer | D17: /my-trips | E17: Redirected to /checkout at counter amount
A18: 10 | B18: Renter 1 | C18: Complete Stripe payment | D18: /booking-success | E18: Booking created at counter price
A19: 11 | B19: Owner 1 | C19: Check Bookings & Earnings | D19: /owner-dashboard | E19: New booking from bid visible
A21: SCENARIO RESULT

Sheet S-06 Travel Request & Owner Pro
A1: S-06: Travel Request & Owner Proposal
A3: Capability: | B3: Post request → Owner proposes → Accept → Book
A4: Roles: | B4: Renter 2 (Liam), Owner 2 (Maria, Marriott)
A5: Est. Time: | B5: 15 min
A6: Preconditions: | B6: Owner 2 has active Marriott listings in Orlando
A8: # | B8: As (Role) | C8: Action | D8: Page | E8: Expected Result | F8: Run 1 | G8: Run 2 | H8: Run 3 | I8: Run 4 | J8: Run 5 | K8: Run 6 | L8: Run 7 | M8: Run 8 | N8: Run 9 | O8: Run 10 | P8: Notes / Bug #
A9: 1 | B9: Renter 2 | C9: Log in → /bidding | D9: /bidding | E9: TravelRequestForm loads
A10: 2 | B10: Renter 2 | C10: Fill: Orlando FL, 45d out, 5 nights, 4 guests, $1000-2000, flexible ±3d → Submit | D10: /bidding | E10: Toast: Travel request posted
A11: 3 | B11: Owner 2 | C11: Log in → /owner-dashboard → travel requests section | D11: /owner-dashboard | E11: Renter 2's matched request visible
A12: 4 | B12: Owner 2 | C12: View request → Submit Proposal | D12: /owner-dashboard | E12: Proposal form opens
A13: 5 | B13: Owner 2 | C13: Select Grande Vista, $1,500, matching dates, add message → Submit | D13: /owner-dashboard | E13: Toast: Proposal sent
A14: 6 | B14: Renter 2 | C14: Check notification bell | D14: Any | E14: Notification: Owner proposal received
A15: 7 | B15: Renter 2 | C15: /my-trips?tab=offers | D15: /my-trips | E15: Proposal with property, price, dates
A16: 8 | B16: Renter 2 | C16: Accept Proposal | D16: /my-trips | E16: Redirected to /checkout
A17: 9 | B17: Renter 2 | C17: Complete Stripe payment | D17: /booking-success | E17: Booking at $1,500
A18: 10 | B18: Owner 2 | C18: Check bookings | D18: /owner-dashboard | E18: Booking from travel request visible
A20: SCENARIO RESULT

Sheet S-07 Pre-Booking Inquiry & Mess
A1: S-07: Pre-Booking Inquiry & Messaging
A3: Capability: | B3: Ask question → Owner replies → Conversation
A4: Roles: | B4: Renter 3 (Olivia, Premium), Owner 3 (James, Disney)
A5: Est. Time: | B5: 8 min
A6: Preconditions: | B6: Owner 3 has active Disney listing
A8: # | B8: As (Role) | C8: Action | D8: Page | E8: Expected Result | F8: Run 1 | G8: Run 2 | H8: Run 3 | I8: Run 4 | J8: Run 5 | K8: Run 6 | L8: Run 7 | M8: Run 8 | N8: Run 9 | O8: Run 10 | P8: Notes / Bug #
A9: 1 | B9: Renter 3 | C9: Log in → find Disney listing → /property/:id | D9: /property/:id | E9: Ask the Owner button visible
A10: 2 | B10: Renter 3 | C10: Click Ask the Owner → type question → Send | D10: /property/:id | E10: Toast: Message sent
A11: 3 | B11: Owner 3 | C11: Log in → check notification bell | D11: Any | E11: Notification: New inquiry
A12: 4 | B12: Owner 3 | C12: Click notification → view InquiryThread | D12: InquiryThread | E12: Renter's message visible
A13: 5 | B13: Owner 3 | C13: Reply with answer → Send | D13: InquiryThread | E13: Reply sent
A14: 6 | B14: Renter 3 | C14: Check notification → view thread | D14: InquiryThread | E14: Owner's reply visible
A15: 7 | B15: Renter 3 | C15: Reply again → Send | D15: InquiryThread | E15: Conversation continues
A17: SCENARIO RESULT

Sheet S-08 Booking Messaging & Realti
A1: S-08: Booking Messaging & Realtime
A3: Capability: | B3: Post-booking thread → Realtime delivery
A4: Roles: | B4: Renter 1, Owner 1
A5: Est. Time: | B5: 8 min
A6: Preconditions: | B6: Confirmed booking between Renter 1 and Owner 1
A8: # | B8: As (Role) | C8: Action | D8: Page | E8: Expected Result | F8: Run 1 | G8: Run 2 | H8: Run 3 | I8: Run 4 | J8: Run 5 | K8: Run 6 | L8: Run 7 | M8: Run 8 | N8: Run 9 | O8: Run 10 | P8: Notes / Bug #
A9: 1 | B9: Renter 1 | C9: /my-trips?tab=bookings → select booking → open messages | D9: /my-trips | E9: BookingMessageThread loads
A10: 2 | B10: Renter 1 | C10: Type message: 'What's the WiFi password?' → Send | D10: /my-trips | E10: Message appears instantly
A11: 3 | B11: Owner 1 | C11: Log in (separate browser) → check bell | D11: Any | E11: Notification arrives (realtime, no refresh)
A12: 4 | B12: Owner 1 | C12: Navigate to booking → open messages | D12: /owner-dashboard | E12: Renter's message visible
A13: 5 | B13: Owner 1 | C13: Reply with WiFi info → Send | D13: /owner-dashboard | E13: Message sent
A14: 6 | B14: Renter 1 | C14: Check thread WITHOUT refreshing | D14: /my-trips | E14: Owner's reply appears in realtime
A16: SCENARIO RESULT

Sheet S-09 Renter Cancellation Flow
A1: S-09: Renter Cancellation Flow
A3: Capability: | B3: Cancel → Policy refund → Status updates
A4: Roles: | B4: Renter 1, Owner 1, RAV Admin
A5: Est. Time: | B5: 10 min
A6: Preconditions: | B6: Confirmed booking between Renter 1 and Owner 1
A8: # | B8: As (Role) | C8: Action | D8: Page | E8: Expected Result | F8: Run 1 | G8: Run 2 | H8: Run 3 | I8: Run 4 | J8: Run 5 | K8: Run 6 | L8: Run 7 | M8: Run 8 | N8: Run 9 | O8: Run 10 | P8: Notes / Bug #
A9: 1 | B9: Renter 1 | C9: /my-trips?tab=bookings → select booking | D9: /my-trips | E9: Cancel Booking option visible
A10: 2 | B10: Renter 1 | C10: Click Cancel Booking | D10: /my-trips | E10: CancelBookingDialog: policy, refund estimate
A11: 3 | B11: Renter 1 | C11: Reason: Change of plans → Confirm | D11: /my-trips | E11: Toast: Cancellation requested
A12: 4 | B12: Renter 1 | C12: View booking in My Trips | D12: /my-trips | E12: Status: Cancelled, refund amount shown
A13: 5 | B13: Owner 1 | C13: Log in → check notification | D13: Any | E13: Notification: Booking cancelled
A14: 6 | B14: Owner 1 | C14: /owner-dashboard?tab=bookings-earnings | D14: /owner-dashboard | E14: Status: Cancelled, listing re-available
A15: 7 | B15: Admin | C15: /admin?tab=bookings | D15: /admin | E15: Cancellation with refund details
A16: 8 | B16: Admin | C16: Verify refund processed | D16: /admin | E16: Refund matches policy (flex/mod/strict)
A18: SCENARIO RESULT

Sheet S-10 Owner Cancellation Flow
A1: S-10: Owner Cancellation Flow
A3: Capability: | B3: Owner cancels → Full refund → Penalty
A4: Roles: | B4: Owner 1, Renter 1, RAV Admin
A5: Est. Time: | B5: 10 min
A6: Preconditions: | B6: Confirmed booking between Owner 1 and Renter 1
A8: # | B8: As (Role) | C8: Action | D8: Page | E8: Expected Result | F8: Run 1 | G8: Run 2 | H8: Run 3 | I8: Run 4 | J8: Run 5 | K8: Run 6 | L8: Run 7 | M8: Run 8 | N8: Run 9 | O8: Run 10 | P8: Notes / Bug #
A9: 1 | B9: Owner 1 | C9: /owner-dashboard?tab=bookings-earnings → select booking | D9: /owner-dashboard | E9: Cancel option visible
A10: 2 | B10: Owner 1 | C10: Click Cancel → dialog warns about penalty | D10: /owner-dashboard | E10: Warning: full refund + cancellation count
A11: 3 | B11: Owner 1 | C11: Select reason → Confirm | D11: /owner-dashboard | E11: Cancellation processed
A12: 4 | B12: Renter 1 | C12: /my-trips?tab=bookings | D12: /my-trips | E12: Status: Cancelled by Owner, full refund
A13: 5 | B13: Renter 1 | C13: Check notification | D13: Any | E13: Notification: Owner cancelled, full refund
A14: 6 | B14: Admin | C14: /admin?tab=bookings | D14: /admin | E14: Owner cancellation logged, refund = 100%
A15: 7 | B15: Owner 1 | C15: Check dashboard | D15: /owner-dashboard | E15: Cancellation count incremented
A17: SCENARIO RESULT

Sheet S-11 Dispute Resolution — Check
A1: S-11: Dispute Resolution — Check-In Issue
A3: Capability: | B3: Report issue → Evidence → Admin resolves
A4: Roles: | B4: Renter 1, RAV Admin
A5: Est. Time: | B5: 12 min
A6: Preconditions: | B6: Confirmed booking at/past check-in date
A8: # | B8: As (Role) | C8: Action | D8: Page | E8: Expected Result | F8: Run 1 | G8: Run 2 | H8: Run 3 | I8: Run 4 | J8: Run 5 | K8: Run 6 | L8: Run 7 | M8: Run 8 | N8: Run 9 | O8: Run 10 | P8: Notes / Bug #
A9: 1 | B9: Renter 1 | C9: /checkin or /my-trips → select booking | D9: Various | E9: Report Issue button visible
A10: 2 | B10: Renter 1 | C10: Click Report Issue → ReportIssueDialog | D10: — | E10: Category dropdown, description, evidence upload
A11: 3 | B11: Renter 1 | C11: Category: Room not as described, add description + photo → Submit | D11: — | E11: Toast: Issue reported
A12: 4 | B12: Renter 1 | C12: /my-trips → booking detail | D12: /my-trips | E12: Dispute status: Under Review
A13: 5 | B13: Admin | C13: /admin?tab=disputes | D13: /admin | E13: New dispute with category, description
A14: 6 | B14: Admin | C14: Click dispute → view evidence thumbnails | D14: /admin | E14: Photos render correctly
A15: 7 | B15: Admin | C15: Add notes, select resolution (full/partial refund) → Resolve | D15: /admin | E15: Status: Resolved
A16: 8 | B16: Renter 1 | C16: Check /my-trips + notification | D16: /my-trips | E16: Dispute resolved, refund details shown
A18: SCENARIO RESULT

Sheet S-12 Owner Earnings & Payout Cy
A1: S-12: Owner Earnings & Payout Cycle
A3: Capability: | B3: Completed booking → Escrow release → Payout
A4: Roles: | B4: Owner 2 (Maria, Business), RAV Admin
A5: Est. Time: | B5: 10 min
A6: Preconditions: | B6: Completed booking for Owner 2 with escrow released
A8: # | B8: As (Role) | C8: Action | D8: Page | E8: Expected Result | F8: Run 1 | G8: Run 2 | H8: Run 3 | I8: Run 4 | J8: Run 5 | K8: Run 6 | L8: Run 7 | M8: Run 8 | N8: Run 9 | O8: Run 10 | P8: Notes / Bug #
A9: 1 | B9: Owner 2 | C9: Log in → /owner-dashboard (Dashboard tab) | D9: /owner-dashboard | E9: Earnings summary: total, pending, paid
A10: 2 | B10: Owner 2 | C10: Bookings & Earnings tab | D10: /owner-dashboard | E10: Completed bookings with amounts
A11: 3 | B11: Owner 2 | C11: Verify commission: total - 10% (Business tier) | D11: /owner-dashboard | E11: Commission calc correct
A12: 4 | B12: Owner 2 | C12: Check Stripe Connect status (StripeConnectBanner) | D12: /owner-dashboard | E12: Connect or Payouts Enabled state
A13: 5 | B13: Admin | C13: /admin?tab=payouts | D13: /admin | E13: Owner 2 pending payout visible
A14: 6 | B14: Admin | C14: Pay via Stripe → Confirm in AlertDialog | D14: /admin | E14: Payout: Processing/Paid
A15: 7 | B15: Owner 2 | C15: Refresh Bookings & Earnings | D15: /owner-dashboard | E15: Payout status: Paid
A17: SCENARIO RESULT

Sheet S-13 Membership Upgrade — Owner
A1: S-13: Membership Upgrade — Owner
A3: Capability: | B3: Free → Pro → Listing limit increase
A4: Roles: | B4: Owner 3 (James, Free → Pro)
A5: Est. Time: | B5: 8 min
A6: Preconditions: | B6: Owner 3 has Free tier (3 listing limit)
A8: # | B8: As (Role) | C8: Action | D8: Page | E8: Expected Result | F8: Run 1 | G8: Run 2 | H8: Run 3 | I8: Run 4 | J8: Run 5 | K8: Run 6 | L8: Run 7 | M8: Run 8 | N8: Run 9 | O8: Run 10 | P8: Notes / Bug #
A9: 1 | B9: Owner 3 | C9: Log in → /owner-dashboard?tab=account | D9: /owner-dashboard | E9: Tier: Free, limit: 3
A10: 2 | B10: Owner 3 | C10: Click Upgrade Plan → MembershipPlans | D10: /owner-dashboard | E10: Tier comparison table
A11: 3 | B11: Owner 3 | C11: Select Pro tier → Stripe Checkout | D11: Stripe | E11: Pro plan at $10/month
A12: 4 | B12: Owner 3 | C12: Complete payment | D12: /subscription-success | E12: Subscription confirmed
A13: 5 | B13: Owner 3 | C13: Return to /owner-dashboard?tab=account | D13: /owner-dashboard | E13: Tier: Pro, limit: 10
A14: 6 | B14: Owner 3 | C14: Navigate to /list-property | D14: /list-property | E14: Can create new listing (was at limit)
A15: 7 | B15: Owner 3 | C15: Check My Listings | D15: /owner-dashboard | E15: Limit shows updated (e.g., 2/10)
A17: SCENARIO RESULT

Sheet S-14 Membership Upgrade — Rente
A1: S-14: Membership Upgrade — Renter
A3: Capability: | B3: Free → Plus → Perks visible
A4: Roles: | B4: Renter 4 (Free → Plus)
A5: Est. Time: | B5: 8 min
A6: Preconditions: | B6: Renter 4 has Free tier
A8: # | B8: As (Role) | C8: Action | D8: Page | E8: Expected Result | F8: Run 1 | G8: Run 2 | H8: Run 3 | I8: Run 4 | J8: Run 5 | K8: Run 6 | L8: Run 7 | M8: Run 8 | N8: Run 9 | O8: Run 10 | P8: Notes / Bug #
A9: 1 | B9: Renter 4 | C9: Log in → /my-trips | D9: /my-trips | E9: Current tier shown, upgrade prompt
A10: 2 | B10: Renter 4 | C10: Click upgrade → MembershipPlans | D10: /my-trips | E10: Free vs Plus ($5) vs Premium ($15)
A11: 3 | B11: Renter 4 | C11: Select Plus → Stripe Checkout | D11: Stripe | E11: Plus at $5/month
A12: 4 | B12: Renter 4 | C12: Complete payment | D12: /subscription-success | E12: Subscription confirmed
A13: 5 | B13: Renter 4 | C13: Return to /my-trips | D13: /my-trips | E13: Tier: Plus, perks visible
A15: SCENARIO RESULT

Sheet S-15 Referral Program End-to-En
A1: S-15: Referral Program End-to-End
A3: Capability: | B3: Generate code → Signup with ref → Track
A4: Roles: | B4: Owner 1, New User (incognito), RAV Admin
A5: Est. Time: | B5: 10 min
A6: Preconditions: | B6: Owner 1 has referral code
A8: # | B8: As (Role) | C8: Action | D8: Page | E8: Expected Result | F8: Run 1 | G8: Run 2 | H8: Run 3 | I8: Run 4 | J8: Run 5 | K8: Run 6 | L8: Run 7 | M8: Run 8 | N8: Run 9 | O8: Run 10 | P8: Notes / Bug #
A9: 1 | B9: Owner 1 | C9: /owner-dashboard?tab=account → Referral section | D9: /owner-dashboard | E9: ReferralDashboard with code + share link
A10: 2 | B10: Owner 1 | C10: Copy referral link | D10: /owner-dashboard | E10: Link copied
A11: 3 | B11: New User | C11: Incognito → paste referral link → /signup?ref=REFxxx | D11: /signup | E11: Signup form with ref param captured
A12: 4 | B12: New User | C12: Complete signup | D12: /signup | E12: Account created, referral recorded
A13: 5 | B13: Admin | C13: Approve new user | D13: /admin | E13: User approved
A14: 6 | B14: Owner 1 | C14: Check ReferralDashboard | D14: /owner-dashboard | E14: Referral count incremented
A16: SCENARIO RESULT

Sheet S-16 Search, Filter & Discovery
A1: S-16: Search, Filter & Discovery
A3: Capability: | B3: Filters → Sort → Compare → Save search
A4: Roles: | B4: Renter 1 (Plus)
A5: Est. Time: | B5: 10 min
A6: Preconditions: | B6: Active listings in seed data
A8: # | B8: As (Role) | C8: Action | D8: Page | E8: Expected Result | F8: Run 1 | G8: Run 2 | H8: Run 3 | I8: Run 4 | J8: Run 5 | K8: Run 6 | L8: Run 7 | M8: Run 8 | N8: Run 9 | O8: Run 10 | P8: Notes / Bug #
A9: 1 | B9: Renter 1 | C9: Log in → /rentals | D9: /rentals | E9: Listing grid with filter bar
A10: 2 | B10: Renter 1 | C10: Filter: Orlando, 2+ bedrooms, $100-300/night | D10: /rentals | E10: Results narrow, count updates
A11: 3 | B11: Renter 1 | C11: Sort: Price Low to High | D11: /rentals | E11: Order correct
A12: 4 | B12: Renter 1 | C12: Sort: Price High to Low | D12: /rentals | E12: Order reverses
A13: 5 | B13: Renter 1 | C13: Click Save Search | D13: /rentals | E13: Toast: Search saved
A14: 6 | B14: Renter 1 | C14: Enable Compare mode | D14: /rentals | E14: Checkboxes appear on cards
A15: 7 | B15: Renter 1 | C15: Select 2-3 listings → Compare | D15: /rentals | E15: CompareListingsDialog with Best Value badges
A16: 8 | B16: Renter 1 | C16: Close → /my-trips?tab=favorites | D16: /my-trips | E16: Saved search visible
A17: 9 | B17: Renter 1 | C17: /destinations | D17: /destinations | E17: 10 destinations with city counts
A18: 10 | B18: Renter 1 | C18: Click destination → city → listings | D18: /destinations/:slug/:city | E18: Filtered listings
A20: SCENARIO RESULT

Sheet S-17 Notification Delivery & Pr
A1: S-17: Notification Delivery & Preferences
A3: Capability: | B3: Trigger event → Notification arrives → Preferences
A4: Roles: | B4: Renter 1, Owner 1
A5: Est. Time: | B5: 10 min
A6: Preconditions: | B6: Active interactions between Renter 1 and Owner 1
A8: # | B8: As (Role) | C8: Action | D8: Page | E8: Expected Result | F8: Run 1 | G8: Run 2 | H8: Run 3 | I8: Run 4 | J8: Run 5 | K8: Run 6 | L8: Run 7 | M8: Run 8 | N8: Run 9 | O8: Run 10 | P8: Notes / Bug #
A9: 1 | B9: Renter 1 | C9: Click notification bell | D9: Any | E9: Unread count + dropdown list
A10: 2 | B10: Renter 1 | C10: Click View All | D10: /notifications | E10: Full feed with category filters
A11: 3 | B11: Renter 1 | C11: Filter by Bookings | D11: /notifications | E11: Only booking notifications
A12: 4 | B12: Renter 1 | C12: /settings/notifications | D12: /settings/notifications | E12: Per-type per-channel toggles
A13: 5 | B13: Renter 1 | C13: Toggle OFF email for Booking updates | D13: /settings/notifications | E13: Preference saved
A14: 6 | B14: — | C14: Trigger a booking event | D14: — | E14: —
A15: 7 | B15: Renter 1 | C15: Verify: in-app notification ✅, email ❌ | D15: Various | E15: Channel preference respected
A16: 8 | B16: Owner 1 | C16: /settings/notifications | D16: /settings/notifications | E16: Owner-specific notification types
A18: SCENARIO RESULT

Sheet S-18 Admin — Full Operations Cy
A1: S-18: Admin — Full Operations Cycle
A3: Capability: | B3: All admin tabs + staff boundary check
A4: Roles: | B4: RAV Admin, RAV Staff
A5: Est. Time: | B5: 15 min
A6: Preconditions: | B6: Seed data loaded
A8: # | B8: As (Role) | C8: Action | D8: Page | E8: Expected Result | F8: Run 1 | G8: Run 2 | H8: Run 3 | I8: Run 4 | J8: Run 5 | K8: Run 6 | L8: Run 7 | M8: Run 8 | N8: Run 9 | O8: Run 10 | P8: Notes / Bug #
A9: 1 | B9: Admin | C9: Log in → /admin | D9: /admin?tab=overview | E9: Overview: KPIs, charts, pending counts
A10: 2 | B10: Admin | C10: Click through Properties tab | D10: /admin?tab=properties | E10: Property list + edit button
A11: 3 | B11: Admin | C11: Listings tab | D11: /admin?tab=listings | E11: Approve/reject queue
A12: 4 | B12: Admin | C12: Bookings tab | D12: /admin?tab=bookings | E12: Booking list + filters
A13: 5 | B13: Admin | C13: Escrow tab | D13: /admin?tab=escrow | E13: Verify/release controls
A14: 6 | B14: Admin | C14: Issues tab | D14: /admin?tab=issues | E14: Check-in issues list
A15: 7 | B15: Admin | C15: Disputes tab | D15: /admin?tab=disputes | E15: Dispute queue + evidence
A16: 8 | B16: Admin | C16: Verifications tab | D16: /admin?tab=verifications | E16: Doc review queue
A17: 9 | B17: Admin | C17: Users tab | D17: /admin?tab=users | E17: User search + roles
A18: 10 | B18: Admin | C18: Approvals tab | D18: /admin?tab=pending-approvals | E18: Pending users + upgrades
A19: 11 | B19: Admin | C19: Financials tab | D19: /admin?tab=financials | E19: Revenue, commissions
A20: 12 | B20: Admin | C20: Tax tab | D20: /admin?tab=tax | E20: 1099-K tracking
... A32: 24 | B32: Staff | C32: Verify admin-only tabs NOT in navigation | D32: /admin | E32: Financials/Tax/etc not visible
A34: SCENARIO RESULT

Sheet S-19 Stripe Payment Edge Cases
A1: S-19: Stripe Payment Edge Cases
A3: Capability: | B3: Decline, 3DS, expired card handling
A4: Roles: | B4: Renter 1
A5: Est. Time: | B5: 10 min
A6: Preconditions: | B6: Active listing for checkout
A8: # | B8: As (Role) | C8: Action | D8: Page | E8: Expected Result | F8: Run 1 | G8: Run 2 | H8: Run 3 | I8: Run 4 | J8: Run 5 | K8: Run 6 | L8: Run 7 | M8: Run 8 | N8: Run 9 | O8: Run 10 | P8: Notes / Bug #
A9: 1 | B9: Renter 1 | C9: Start checkout for a listing | D9: /checkout | E9: Payment form loads
A10: 2 | B10: Renter 1 | C10: Card: 4000 0000 0000 9995 (insufficient funds) | D10: /checkout | E10: Error: Insufficient funds
A11: 3 | B11: Renter 1 | C11: Card: 4000 0000 0000 0002 (decline) | D11: /checkout | E11: Error: Card declined
A12: 4 | B12: Renter 1 | C12: Card: 4000 0000 0000 0069 (expired) | D12: /checkout | E12: Error: Card expired
A13: 5 | B13: Renter 1 | C13: Card: 4000 0027 6000 3184 (3DS) → complete auth | D13: /checkout | E13: 3DS popup → payment succeeds
A14: 6 | B14: Renter 1 | C14: New checkout → Card: 4000 0084 0000 1629 (3DS fail) | D14: /checkout | E14: 3DS popup → payment declined
A16: SCENARIO RESULT

Sheet S-20 Public Pages & Unauthentic
A1: S-20: Public Pages & Unauthenticated Access
A3: Capability: | B3: All public routes + protected route guards
A4: Roles: | B4: Guest (logged out)
A5: Est. Time: | B5: 10 min
A6: Preconditions: | B6: Logged out / incognito browser
A8: # | B8: As (Role) | C8: Action | D8: Page | E8: Expected Result | F8: Run 1 | G8: Run 2 | H8: Run 3 | I8: Run 4 | J8: Run 5 | K8: Run 6 | L8: Run 7 | M8: Run 8 | N8: Run 9 | O8: Run 10 | P8: Notes / Bug #
A9: 1 | B9: Guest | C9: Navigate to / | D9: / | E9: Landing page: hero, features, properties
A10: 2 | B10: Guest | C10: /how-it-works | D10: /how-it-works | E10: Page loads with sections
A11: 3 | B11: Guest | C11: /destinations | D11: /destinations | E11: 10 destinations with counts
A12: 4 | B12: Guest | C12: /faq | D12: /faq | E12: FAQ accordion loads
A13: 5 | B13: Guest | C13: /terms | D13: /terms | E13: Terms renders
A14: 6 | B14: Guest | C14: /privacy | D14: /privacy | E14: Privacy renders
A15: 7 | B15: Guest | C15: /contact | D15: /contact | E15: Contact form loads
A16: 8 | B16: Guest | C16: /tools | D16: /tools | E16: 5 tools listed
A17: 9 | B17: Guest | C17: /calculator | D17: /calculator | E17: SmartEarn works without login
A18: 10 | B18: Guest | C18: /developers | D18: /developers | E18: API docs / Swagger loads
A19: 11 | B19: Guest | C19: /user-guide | D19: /user-guide | E19: User guide renders
A20: 12 | B20: Guest | C20: /login | D20: /login | E20: Login form + Google OAuth
... A25: 17 | B25: Guest | C25: /nonexistent-page | D25: 404 | E25: Custom 404 page
A27: SCENARIO RESULT

Sheet S-21 Owner Multi-Listing Manage
A1: S-21: Owner Multi-Listing Management
A3: Capability: | B3: Multiple listings, tier limits, drafts
A4: Roles: | B4: Owner 3 (Free, 3 listing limit)
A5: Est. Time: | B5: 10 min
A6: Preconditions: | B6: Owner 3 has Free tier (3 listing limit)
A8: # | B8: As (Role) | C8: Action | D8: Page | E8: Expected Result | F8: Run 1 | G8: Run 2 | H8: Run 3 | I8: Run 4 | J8: Run 5 | K8: Run 6 | L8: Run 7 | M8: Run 8 | N8: Run 9 | O8: Run 10 | P8: Notes / Bug #
A9: 1 | B9: Owner 3 | C9: /owner-dashboard?tab=my-listings | D9: /owner-dashboard | E9: Listing count shown (e.g., 2/3)
A10: 2 | B10: Owner 3 | C10: /list-property → start filling → navigate away | D10: /list-property | E10: Form auto-saves to localStorage
A11: 3 | B11: Owner 3 | C11: Return to /list-property | D11: /list-property | E11: Draft restored from localStorage
A12: 4 | B12: Owner 3 | C12: Complete and submit listing | D12: /list-property | E12: Submitted (now at 3/3 limit)
A13: 5 | B13: Owner 3 | C13: Try /list-property again | D13: /list-property | E13: Warning: Reached limit, upgrade link
A14: 6 | B14: Owner 3 | C14: Edit existing listing in My Listings | D14: /owner-dashboard | E14: Edit dialog: nightly rate, dates, policy
A15: 7 | B15: Owner 3 | C15: Verify listing statuses | D15: /owner-dashboard | E15: Each shows correct status
A17: SCENARIO RESULT

Sheet S-22 RAV Smart Tools Suite
A1: S-22: RAV Smart Tools Suite
A3: Capability: | B3: SmartEarn, SmartCompare, SmartMatch, SmartBudget
A4: Roles: | B4: Guest (any user or logged out)
A5: Est. Time: | B5: 10 min
A6: Preconditions: | B6: None
A8: # | B8: As (Role) | C8: Action | D8: Page | E8: Expected Result | F8: Run 1 | G8: Run 2 | H8: Run 3 | I8: Run 4 | J8: Run 5 | K8: Run 6 | L8: Run 7 | M8: Run 8 | N8: Run 9 | O8: Run 10 | P8: Notes / Bug #
A9: 1 | B9: Guest | C9: /tools | D9: /tools | E9: Hub: 5 tools with descriptions
A10: 2 | B10: Guest | C10: /calculator → Hilton, $2400/yr, 1 week → Calculate | D10: /calculator | E10: Breakeven analysis + bar chart
A11: 3 | B11: Guest | C11: Toggle Yield Estimator mode | D11: /calculator | E11: ROI % + projected earnings
A12: 4 | B12: Guest | C12: /tools/cost-comparator → hotel $300/night, 7 nights | D12: /tools/cost-comparator | E12: Hotel vs timeshare vs RAV comparison
A13: 5 | B13: Guest | C13: /tools/resort-quiz → answer questions | D13: /tools/resort-quiz | E13: Results: matched resorts with scores
A14: 6 | B14: Guest | C14: /tools/budget-planner → fill inputs | D14: /tools/budget-planner | E14: Budget breakdown rendered
A15: 7 | B15: Guest | C15: Verify breadcrumbs navigate to /tools | D15: All tool pages | E15: Breadcrumbs work
A17: SCENARIO RESULT

Sheet S-23 Date Proposal & Flexible B
A1: S-23: Date Proposal & Flexible Booking
A3: Capability: | B3: Propose alt dates → Owner reviews → Accept
A4: Roles: | B4: Renter 1, Owner 1
A5: Est. Time: | B5: 12 min
A6: Preconditions: | B6: Active bidding listing from Owner 1
A8: # | B8: As (Role) | C8: Action | D8: Page | E8: Expected Result | F8: Run 1 | G8: Run 2 | H8: Run 3 | I8: Run 4 | J8: Run 5 | K8: Run 6 | L8: Run 7 | M8: Run 8 | N8: Run 9 | O8: Run 10 | P8: Notes / Bug #
A9: 1 | B9: Renter 1 | C9: Find bidding listing → Make an Offer | D9: /property/:id | E9: BidFormDialog in bid mode
A10: 2 | B10: Renter 1 | C10: Switch to Propose Different Dates mode | D10: /property/:id | E10: Date pickers + auto-computed bid
A11: 3 | B11: Renter 1 | C11: Select different check-in/out, verify auto-calc | D11: /property/:id | E11: Bid = nightly_rate × nights
A12: 4 | B12: Renter 1 | C12: Add message → Submit | D12: /property/:id | E12: Toast: Date proposal submitted
A13: 5 | B13: Owner 1 | C13: My Listings → BidsManagerDialog | D13: /owner-dashboard | E13: Date proposal with proposed dates + amount
A14: 6 | B14: Owner 1 | C14: Accept or counter the date proposal | D14: /owner-dashboard | E14: Response sent
A15: 7 | B15: Renter 1 | C15: /my-trips?tab=offers | D15: /my-trips | E15: Date proposal response visible
A17: SCENARIO RESULT

Sheet S-24 Admin Property & Listing E
A1: S-24: Admin Property & Listing Editing
A3: Capability: | B3: Edit property/listing details, audit trail
A4: Roles: | B4: RAV Admin
A5: Est. Time: | B5: 10 min
A6: Preconditions: | B6: Existing properties and listings in seed data
A8: # | B8: As (Role) | C8: Action | D8: Page | E8: Expected Result | F8: Run 1 | G8: Run 2 | H8: Run 3 | I8: Run 4 | J8: Run 5 | K8: Run 6 | L8: Run 7 | M8: Run 8 | N8: Run 9 | O8: Run 10 | P8: Notes / Bug #
A9: 1 | B9: Admin | C9: /admin?tab=properties → select property | D9: /admin | E9: Property details visible
A10: 2 | B10: Admin | C10: Click Edit → AdminPropertyEditDialog | D10: /admin | E10: Fields: brand, resort, bedrooms, etc.
A11: 3 | B11: Admin | C11: Change bedrooms 2→3 → Save | D11: /admin | E11: Success toast, property updated
A12: 4 | B12: Admin | C12: Verify audit trail: edited by + timestamp | D12: /admin | E12: last_edited_by/at populated
A13: 5 | B13: Admin | C13: /admin?tab=listings → select active listing | D13: /admin | E13: Listing with pricing
A14: 6 | B14: Admin | C14: Click Edit → AdminListingEditDialog | D14: /admin | E14: Live price calc visible
A15: 7 | B15: Admin | C15: Change nightly rate → observe recalculation | D15: /admin | E15: Owner price, markup, final update live
A16: 8 | B16: Admin | C16: Save changes | D16: /admin | E16: Listing updated
A17: 9 | B17: Admin | C17: Try editing booked/completed listing | D17: /admin | E17: Edit disabled or blocked
A19: SCENARIO RESULT

Sheet S-25 Executive Dashboard & Anal
A1: S-25: Executive Dashboard & Analytics
A3: Capability: | B3: Strategic metrics, market data
A4: Roles: | B4: RAV Owner (dev-owner@)
A5: Est. Time: | B5: 8 min
A6: Preconditions: | B6: Seed data loaded
A8: # | B8: As (Role) | C8: Action | D8: Page | E8: Expected Result | F8: Run 1 | G8: Run 2 | H8: Run 3 | I8: Run 4 | J8: Run 5 | K8: Run 6 | L8: Run 7 | M8: Run 8 | N8: Run 9 | O8: Run 10 | P8: Notes / Bug #
A9: 1 | B9: RAV Owner | C9: /executive-dashboard | D9: /executive-dashboard | E9: Dashboard loads with data
A10: 2 | B10: RAV Owner | C10: Verify KPI cards: GMV, listings, users, conversion | D10: /executive-dashboard | E10: Numbers render from seed data
A11: 3 | B11: RAV Owner | C11: Check liquidity score | D11: /executive-dashboard | E11: Score + explanation renders
A12: 4 | B12: RAV Owner | C12: Verify unit economics section | D12: /executive-dashboard | E12: Commission, avg booking, CAC
A13: 5 | B13: RAV Owner | C13: Check market benchmarks | D13: /executive-dashboard | E13: Section renders
A14: 6 | B14: Staff | C14: Log in as dev-staff → /executive-dashboard | D14: /executive-dashboard | E14: Access denied or redirected
A16: SCENARIO RESULT

Sheet S-26 Voice Search & Quota Manag
A1: S-26: Voice Search & Quota Management
A3: Capability: | B3: Voice search → Quota tracking → Admin override
A4: Roles: | B4: Renter 1 (Plus, 25/day), RAV Admin
A5: Est. Time: | B5: 10 min
A6: Preconditions: | B6: VAPI configured on DEV
A8: # | B8: As (Role) | C8: Action | D8: Page | E8: Expected Result | F8: Run 1 | G8: Run 2 | H8: Run 3 | I8: Run 4 | J8: Run 5 | K8: Run 6 | L8: Run 7 | M8: Run 8 | N8: Run 9 | O8: Run 10 | P8: Notes / Bug #
A9: 1 | B9: Renter 1 | C9: /rentals → click voice search icon | D9: /rentals | E9: Voice UI activates
A10: 2 | B10: Renter 1 | C10: Search: 'Beach vacation in Orlando' | D10: /rentals | E10: Results filter, search logged
A11: 3 | B11: Admin | C11: /admin?tab=voice → VoiceUsageDashboard | D11: /admin | E11: Renter 1's search in chart
A12: 4 | B12: Admin | C12: VoiceUserOverrideManager → find Renter 1 | D12: /admin | E12: User found
A13: 5 | B13: Admin | C13: Set custom quota: 50/day | D13: /admin | E13: Override saved
A14: 6 | B14: Admin | C14: Alternatively: disable voice for user | D14: /admin | E14: Disabled flag saved
A15: 7 | B15: Renter 1 | C15: If disabled: try voice search | D15: /rentals | E15: Voice search disabled message
A16: 8 | B16: Admin | C16: VoiceObservability → log viewer | D16: /admin | E16: Recent logs with query, duration, count
A18: SCENARIO RESULT

Sheet S-27 API Key & Developer Portal
A1: S-27: API Key & Developer Portal
A3: Capability: | B3: Create key → Test endpoint → Revoke
A4: Roles: | B4: RAV Admin
A5: Est. Time: | B5: 10 min
A6: Preconditions: | B6: None
A8: # | B8: As (Role) | C8: Action | D8: Page | E8: Expected Result | F8: Run 1 | G8: Run 2 | H8: Run 3 | I8: Run 4 | J8: Run 5 | K8: Run 6 | L8: Run 7 | M8: Run 8 | N8: Run 9 | O8: Run 10 | P8: Notes / Bug #
A9: 1 | B9: Admin | C9: /admin?tab=api-keys | D9: /admin | E9: API key management loads
A10: 2 | B10: Admin | C10: Create Key: name 'Test Key', tier 'partner', optional IPs | D10: /admin | E10: Key shown ONCE — copy it
A11: 3 | B11: Admin | C11: Verify key in list (masked rav_...) | D11: /admin | E11: Key listed with date, tier
A12: 4 | B12: Guest | C12: /developers | D12: /developers | E12: Swagger UI loads
A13: 5 | B13: Admin | C13: Test API: GET /api/listings with key header | D13: — | E13: Returns JSON, rate limit headers
A14: 6 | B14: Admin | C14: Revoke key → confirm AlertDialog | D14: /admin | E14: Key revoked
A15: 7 | B15: Admin | C15: Test same API call with revoked key | D15: — | E15: 401 Unauthorized
A17: SCENARIO RESULT

Sheet S-28 iCal Export & Calendar Int
A1: S-28: iCal Export & Calendar Integration
A3: Capability: | B3: Export bookings → Verify ICS file
A4: Roles: | B4: Owner 1 (Alex)
A5: Est. Time: | B5: 5 min
A6: Preconditions: | B6: Owner 1 has bookings
A8: # | B8: As (Role) | C8: Action | D8: Page | E8: Expected Result | F8: Run 1 | G8: Run 2 | H8: Run 3 | I8: Run 4 | J8: Run 5 | K8: Run 6 | L8: Run 7 | M8: Run 8 | N8: Run 9 | O8: Run 10 | P8: Notes / Bug #
A9: 1 | B9: Owner 1 | C9: /owner-dashboard?tab=bookings-earnings | D9: /owner-dashboard | E9: Booking list visible
A10: 2 | B10: Owner 1 | C10: Click Export Calendar | D10: /owner-dashboard | E10: ICS file downloads
A11: 3 | B11: Owner 1 | C11: Open ICS in text editor | D11: Local | E11: Valid iCal: BEGIN:VCALENDAR, events
A12: 4 | B12: Owner 1 | C12: Verify dates match bookings, property names correct | D12: Local | E12: Data accurate
A14: SCENARIO RESULT

Sheet S-29 GDPR Data Export & Deletio
A1: S-29: GDPR Data Export & Deletion
A3: Capability: | B3: Request export → Deletion → Grace period
A4: Roles: | B4: Renter 50 (expendable account)
A5: Est. Time: | B5: 8 min
A6: Preconditions: | B6: Use renter050@ (can afford to lose)
A8: # | B8: As (Role) | C8: Action | D8: Page | E8: Expected Result | F8: Run 1 | G8: Run 2 | H8: Run 3 | I8: Run 4 | J8: Run 5 | K8: Run 6 | L8: Run 7 | M8: Run 8 | N8: Run 9 | O8: Run 10 | P8: Notes / Bug #
A9: 1 | B9: Renter 50 | C9: Log in → /account | D9: /account | E9: Account settings loads
A10: 2 | B10: Renter 50 | C10: Click Export My Data | D10: /account | E10: Data export (JSON/download)
A11: 3 | B11: Renter 50 | C11: Click Delete My Account | D11: /account | E11: Warning: 14-day grace, irreversible
A12: 4 | B12: Renter 50 | C12: Confirm deletion | D12: /account | E12: Account marked for deletion, logged out
A13: 5 | B13: Renter 50 | C13: Try to log back in | D13: /login | E13: Grace period message or cancel option
A15: SCENARIO RESULT

Sheet S-30 Complete Marketplace Cycle
A1: S-30: Complete Marketplace Cycle
A3: Capability: | B3: Full lifecycle: list → bid → book → confirm → review → payout
A4: Roles: | B4: Owner 1, Renter 1, RAV Admin
A5: Est. Time: | B5: 25 min
A6: Preconditions: | B6: Reseeded DEV data recommended
A8: # | B8: As (Role) | C8: Action | D8: Page | E8: Expected Result | F8: Run 1 | G8: Run 2 | H8: Run 3 | I8: Run 4 | J8: Run 5 | K8: Run 6 | L8: Run 7 | M8: Run 8 | N8: Run 9 | O8: Run 10 | P8: Notes / Bug #
A9: 1 | B9: Owner 1 | C9: /list-property → Create listing: Hilton Las Vegas, 2BR, 7 nights, $250/night, Open for Bidding | D9: /list-property | E9: Submitted, Pending Approval
A10: 2 | B10: Admin | C10: /admin?tab=listings → Approve Owner 1's listing | D10: /admin | E10: Status: Active
A11: 3 | B11: Renter 1 | C11: /rentals → search Las Vegas → find new listing | D11: /rentals | E11: Listing with bidding badge
A12: 4 | B12: Renter 1 | C12: Ask the Owner: 'Is parking included?' | D12: /property/:id | E12: Inquiry sent
A13: 5 | B13: Owner 1 | C13: Check notification → reply: 'Yes, free parking!' | D13: InquiryThread | E13: Reply sent
A14: 6 | B14: Renter 1 | C14: View reply → Place Bid at $1,500 | D14: /property/:id | E14: Bid submitted
A15: 7 | B15: Owner 1 | C15: BidsManagerDialog → counter at $1,750 | D15: /owner-dashboard | E15: Counter sent
A16: 8 | B16: Renter 1 | C16: Accept counter in My Trips | D16: /my-trips | E16: Redirected to /checkout at $1,750
A17: 9 | B17: Renter 1 | C17: Pay with Stripe test card | D17: /booking-success | E17: Booking: Payment ✅, Owner ⏳
A18: 10 | B18: Owner 1 | C18: Confirm booking → RST confirmation number | D18: /owner-dashboard | E18: Booking confirmed
A19: 11 | B19: Renter 1 | C19: /my-trips → Confirmed status | D19: /my-trips | E19: Timeline updated
A20: 12 | B20: Admin | C20: /admin?tab=escrow → verify → release | D20: /admin | E20: Escrow released
... A26: 18 | B26: Owner 1 | C26: Verify payout status: Paid | D26: /owner-dashboard | E26: Payout: Paid
A28: SCENARIO RESULT

Sheet Reference
A1: Test Account Reference
A2: Universal Password: SeedTest2026!
A4: RAV TEAM ACCOUNTS
A5: Alias | B5: Email | C5: Role | D5: Access | E5: Tier | F5: Notes | G5: Stripe ID
A6: RAV Owner | B6: dev-owner@rent-a-vacation.com | C6: rav_owner | D6: Full admin (all 19 tabs) | E6: — | F6: Platform owner | G6: —
A7: RAV Admin | B7: dev-admin@rent-a-vacation.com | C7: rav_admin | D7: Admin (all 19 tabs) | E7: — | F7: Admin operations | G7: —
A8: RAV Staff | B8: dev-staff@rent-a-vacation.com | C8: rav_staff | D8: Staff (10 operational tabs) | E8: — | F8: Operational only | G8: —
A10: PROPERTY OWNER ACCOUNTS
A11: Alias | B11: Email | C11: Role | D11: Access | E11: Tier | F11: Notes | G11: Stripe ID
A12: Owner 1 | B12: owner1@rent-a-vacation.com | C12: property_owner | D12: Owner dashboard, 10 listings | E12: Pro | F12: Alex Rivera, Hilton | G12: cus_test_owner1_pro
A13: Owner 2 | B13: owner2@rent-a-vacation.com | C13: property_owner | D13: Owner dashboard, 25 listings | E13: Business | F13: Maria Chen, Marriott | G13: cus_test_owner2_biz
A14: Owner 3 | B14: owner3@rent-a-vacation.com | C14: property_owner | D14: Owner dashboard, 3 listings | E14: Free | F14: James Thompson, Disney | G14: —
A15: Owner 4 | B15: owner4@rent-a-vacation.com | C15: property_owner | D15: Owner dashboard, 3 listings | E15: Free | F15: Priya Patel, Wyndham | G15: —
A16: Owner 5 | B16: owner5@rent-a-vacation.com | C16: property_owner | D16: Owner dashboard, 3 listings | E16: Free | F16: Robert Kim, Bluegreen | G16: —
A18: KEY RENTER ACCOUNTS
A19: Alias | B19: Email | C19: Role | D19: Access | E19: Tier | F19: Notes | G19: Stripe ID
A20: Renter 1 | B20: renter001@rent-a-vacation.com | C20: renter | D20: Marketplace + My Trips | E20: Plus | F20: Sophia Martinez | G20: cus_test_renter1_plus
A21: Renter 2 | B21: renter002@rent-a-vacation.com | C21: renter | D21: Marketplace + My Trips | E21: Plus | F21: Liam Johnson | G21: cus_test_renter2_plus
A22: Renter 3 | B22: renter003@rent-a-vacation.com | C22: renter | D22: Marketplace + My Trips | E22: Premium | F22: Olivia Williams | G22: cus_test_renter3_prem
A23: Renter 4 | B23: renter004@rent-a-vacation.com | C23: renter | D23: Marketplace + My Trips | E23: Free | F23: — | G23: —
A24: Renter 50 | B24: renter050@rent-a-vacation.com | C24: renter | D24: Marketplace + My Trips | E24: Free | F24: Expendable (GDPR test) | G24: —
A26: STRIPE TEST CARDS
A27: Scenario | B27: Card Number | C27: CVC | D27: Expiry | E27: ZIP | F27: Expected | G27: Used In
A28: Success (default) | B28: 4242 4242 4242 4242 | C28: 123 | D28: 12/28 | E28: 32256 | F28: Payment completes | G28: S-04, S-05, S-06, S-30
A29: Visa debit | B29: 4000 0566 5566 5556 | C29: 123 | D29: 12/28 | E29: 32256 | F29: Payment completes | G29: S-19
A30: Insufficient funds | B30: 4000 0000 0000 9995 | C30: 123 | D30: 12/28 | E30: 32256 | F30: Decline: insufficient | G30: S-19
A31: Generic decline | B31: 4000 0000 0000 0002 | C31: 123 | D31: 12/28 | E31: 32256 | F31: Decline: generic | G31: S-19
A32: Expired card | B32: 4000 0000 0000 0069 | C32: 123 | D32: 12/28 | E32: 32256 | F32: Decline: expired | G32: S-19
A33: 3D Secure (pass) | B33: 4000 0027 6000 3184 | C33: 123 | D33: 12/28 | E33: 32256 | F33: 3DS popup → success | G33: S-19
A34: 3D Secure (fail) | B34: 4000 0084 0000 1629 | C34: 123 | D34: 12/28 | E34: 32256 | F34: 3DS popup → decline | G34: S-19
A36: ENVIRONMENT
A37: DEV URL | B37: https://dev.rent-a-vacation.com
